<?xml version="1.0" encoding="utf-8"?>

    
<robot name="autocar">
    <!--
        Front Right Gazebo tag
    -->
    <gazebo reference="susp_front_right_prismatic">
        <implicitSpringDamper>true</implicitSpringDamper>
        <springStiffness>250</springStiffness>
        <springReference>0.05</springReference>
    </gazebo>
    <!--
        Front left Gazebo tag
    -->
    <gazebo reference="susp_front_left_prismatic">
        <implicitSpringDamper>true</implicitSpringDamper>
        <springStiffness>250</springStiffness>
        <springReference>0.05</springReference>
    </gazebo>
    <!--
        Rear right gazebo tag
    -->
    <gazebo reference="susp_rear_right_prismatic">
        <implicitSpringDamper>true</implicitSpringDamper>
        <springStiffness>250</springStiffness>
        <springReference>0.05</springReference>
    </gazebo>
    <!--
        Rear left gazebo tag
    -->
    <gazebo reference="susp_rear_left_prismatic">
        <implicitSpringDamper>true</implicitSpringDamper>
        <springStiffness>250</springStiffness>
        <springReference>0.05</springReference>
    </gazebo>
    <link name="autocar_footprint"/>
    <joint name="autocar_footprint_joint" type="fixed">
        <origin rpy="0 0 0" xyz="0 0 0"/>
        <parent link="autocar_footprint"/>
        <child link="chassis"/>
    </joint>
    <!-- Chassis -->
    <link name="chassis">
        <inertial>
            <origin xyz="0.0 0.0 0.15" rpy="0.0 0.0 0.0"/>
            <mass value="5.0"/>
            <inertia ixx="0.216666666666667" ixy="0.841666666666667" ixz="1.04166666666667" iyy="0.0" iyz="0.0" izz="0.0"/>
        </inertial>
        <visual name="chassis_visual">
            <origin xyz="0.0 0.0 0.0" rpy="0.0 0.0 0.0"/>
            <geometry>
                <box size="1.0 0.5 0.1"/>
            </geometry>
            <material name="">
                <color rgba="1.0 0.0 0.0 1.0"/>
            </material>
        </visual>
        <collision>
            <origin xyz="0.0 0.0 0.0" rpy="0.0 0.0 0.0"/>
            <geometry>
                <box size="1.0 0.5 0.1"/>
            </geometry>
        </collision>
    </link>
    <!-- 
        Front Right
    -->
    <!-- Suspension Front right -->
    <link name="suspension_front_right">
        <inertial>
            <origin xyz="0.5 -0.298 0.15" rpy="0.0 0.0 0.0"/>
            <mass value="0.5"/>
            <inertia ixx="0.0002083" ixy="0.0002083" ixz="0.0002083" iyy="0.0" iyz="0.0" izz="0.0"/>
        </inertial>
        <visual name="sus_front_right_vis">
            <origin xyz="0.0 0.0 0.0" rpy="0.0 0.0 0.0"/>
            <geometry>
                <box size="0.05 0.05 0.05"/>
            </geometry>
            <material name="">
                <color rgba="1.0 0.0 0.0 1.0"/>
                <texture filename=""/>
            </material>
        </visual>
        <collision>
            <origin xyz="0.0 0.0 0.0" rpy="0.0 0.0 0.0"/>
            <geometry>
                <box size="0.05 0.05 0.05"/>
            </geometry>
        </collision>
    </link>
    <!-- Prismatic for Front Right suspension -->
    <joint name="susp_front_right_prismatic" type="prismatic">
        <origin xyz="0.5 -0.298 0.0" rpy="0.0 0.0 0.0"/>
        <parent link="chassis"/>
        <child link="suspension_front_right"/>
        <axis xyz="0.0 0.0 -1.0"/>
        <limit lower="-0.0375" upper="0.0375" effort="0.0" velocity="0.0"/>
        <dynamics damping="100"/>
    </joint>
    <!-- Wheel front right -->
    <link name="wheel_front_right">
        <inertial>
            <origin xyz="0.5 -0.298 0.15" rpy="-1.5707963267949 0.0 0.0"/>
            <mass value="0.5"/>
            <inertia ixx="0.0030791" ixy="0.0030791" ixz="0.005625" iyy="0.0" iyz="0.0" izz="0.0"/>
        </inertial>
        <visual name="wheel_fr_visual">
            <origin xyz="0.0 0.0 0.0" rpy="0.0 0.0 0.0"/>
            <geometry>
                <cylinder radius="0.15" length="0.08"/>
            </geometry>
            <material name="">
                <color rgba="1.0 0.0 0.0 1.0"/>
                <texture filename=""/>
            </material>
        </visual>
        <collision>
            <origin xyz="0.0 0.0 0.0" rpy="0.0 0.0 0.0"/>
            <geometry>
                <cylinder radius="0.15" length="0.08"/>
            </geometry>
        </collision>
    </link>
    <joint name="wheel_fr_joint" type="continuous">
        <origin xyz="0.0 0.0 0.0" rpy="-1.5707963267949 0.0 0.0"/>
        <parent link="suspension_front_right"/>
        <child link="wheel_front_right"/>
        <axis xyz="0.0 0.0 1.0"/>
        <dynamics damping="0.5"/>
    </joint>

    <!--
        Front Left
    -->
    <!-- Front left suspension -->
    <link name="suspension_front_left">
        <inertial>
            <origin xyz="0.5 0.298 0.15" rpy="0.0 0.0 0.0"/>
            <mass value="0.5"/>
            <inertia ixx="0.0002083" ixy="0.0002083" ixz="0.0002083" iyy="0.0" iyz="0.0" izz="0.0"/>
        </inertial>
        <visual name="sus_front_left_vis">
            <origin xyz="0.0 0.0 0.0" rpy="0.0 0.0 0.0"/>
            <geometry>
                <box size="0.05 0.05 0.05"/>
            </geometry>
            <material name="">
                <color rgba="1.0 0.0 0.0 1.0"/>
                <texture filename=""/>
            </material>
        </visual>
        <collision>
            <origin xyz="0.0 0.0 0.0" rpy="0.0 0.0 0.0"/>
            <geometry>
                <box size="0.05 0.05 0.05"/>
            </geometry>
        </collision>
    </link>
    <!-- Prismatic for Front left suspension -->
    <joint name="susp_front_left_prismatic" type="prismatic">
        <origin xyz="0.5 0.298 0.0" rpy="0.0 0.0 0.0"/>
        <parent link="chassis"/>
        <child link="suspension_front_left"/>
        <axis xyz="0.0 0.0 -1.0"/>
        <limit lower="-0.0375" upper="0.0375" effort="0.0" velocity="0.0"/>
        <dynamics damping="100"/>
    </joint>
    <!-- Wheel front left -->
    <link name="wheel_front_left">
        <inertial>
            <origin xyz="0.5 0.298 0.15" rpy="-1.5707963267949 0.0 0.0"/>
            <mass value="0.5"/>
            <inertia ixx="0.0030791" ixy="0.0030791" ixz="0.005625" iyy="0.0" iyz="0.0" izz="0.0"/>
        </inertial>
        <visual name="wheel_fl_visual">
            <origin xyz="0.0 0.0 0.0" rpy="0.0 0.0 0.0"/>
            <geometry>
                <cylinder radius="0.15" length="0.08"/>
            </geometry>
            <material name="">
                <color rgba="1.0 0.0 0.0 1.0"/>
                <texture filename=""/>
            </material>
        </visual>
        <collision>
            <origin xyz="0.0 0.0 0.0" rpy="0.0 0.0 0.0"/>
            <geometry>
                <cylinder radius="0.15" length="0.08"/>
            </geometry>
        </collision>
    </link>
    <joint name="wheel_fl_joint" type="continuous">
        <origin xyz="0.0 0.0 0.0" rpy="-1.5707963267949 0.0 0.0"/>
        <parent link="suspension_front_left"/>
        <child link="wheel_front_left"/>
        <axis xyz="0.0 0.0 1.0"/>
        <dynamics damping="0.5"/>
    </joint>
    <!--
        Rear right
    -->
    <link name="suspension_rear_right">
        <inertial>
            <origin xyz="-0.5 -0.298 0.15" rpy="0.0 0.0 0.0"/>
            <mass value="0.5"/>
            <inertia ixx="0.0002083" ixy="0.0002083" ixz="0.0002083" iyy="0.0" iyz="0.0" izz="0.0"/>
        </inertial>
        <visual name="sus_rear_right_vis">
            <origin xyz="0.0 0.0 0.0" rpy="0.0 0.0 0.0"/>
            <geometry>
                <box size="0.05 0.05 0.05"/>
            </geometry>
            <material name="">
                <color rgba="1.0 0.0 0.0 1.0"/>
                <texture filename=""/>
            </material>
        </visual>
        <collision>
            <origin xyz="0.0 0.0 0.0" rpy="0.0 0.0 0.0"/>
            <geometry>
                <box size="0.05 0.05 0.05"/>
            </geometry>
        </collision>
    </link>
    <!-- Prismatic for rear right suspension -->
    <joint name="susp_rear_right_prismatic" type="prismatic">
        <origin xyz="-0.5 -0.298 0.0" rpy="0.0 0.0 0.0"/>
        <parent link="chassis"/>
        <child link="suspension_rear_right"/>
        <axis xyz="0.0 0.0 -1.0"/>
        <limit lower="-0.0375" upper="0.0375" effort="0.0" velocity="0.0"/>
        <dynamics damping="100"/>
    </joint>
    <!-- Wheel rear right -->
    <link name="wheel_rear_right">
        <inertial>
            <origin xyz="-0.5 -0.298 0.15" rpy="-1.5707963267949 0.0 0.0"/>
            <mass value="0.5"/>
            <inertia ixx="0.0030791" ixy="0.0030791" ixz="0.005625" iyy="0.0" iyz="0.0" izz="0.0"/>
        </inertial>
        <visual name="wheel_rr_visual">
            <origin xyz="0.0 0.0 0.0" rpy="0.0 0.0 0.0"/>
            <geometry>
                <cylinder radius="0.15" length="0.08"/>
            </geometry>
            <material name="">
                <color rgba="1.0 0.0 0.0 1.0"/>
                <texture filename=""/>
            </material>
        </visual>
        <collision>
            <origin xyz="0.0 0.0 0.0" rpy="0.0 0.0 0.0"/>
            <geometry>
                <cylinder radius="0.15" length="0.08"/>
            </geometry>
        </collision>
    </link>
    <joint name="wheel_rr_joint" type="continuous">
        <origin xyz="0.0 0.0 0.0" rpy="-1.5707963267949 0.0 0.0"/>
        <parent link="suspension_rear_right"/>
        <child link="wheel_rear_right"/>
        <axis xyz="0.0 0.0 1.0"/>
        <dynamics damping="0.5"/>
    </joint>
    <!-- 
        Rear left
    -->
    <link name="suspension_rear_left">
        <inertial>
            <origin xyz="-0.5 0.298 0.15" rpy="0.0 0.0 0.0"/>
            <mass value="0.5"/>
            <inertia ixx="0.0002083" ixy="0.0002083" ixz="0.0002083" iyy="0.0" iyz="0.0" izz="0.0"/>
        </inertial>
        <visual name="sus_rear_left_vis">
            <origin xyz="0.0 0.0 0.0" rpy="0.0 0.0 0.0"/>
            <geometry>
                <box size="0.05 0.05 0.05"/>
            </geometry>
            <material name="">
                <color rgba="1.0 0.0 0.0 1.0"/>
                <texture filename=""/>
            </material>
        </visual>
        <collision>
            <origin xyz="0.0 0.0 0.0" rpy="0.0 0.0 0.0"/>
            <geometry>
                <box size="0.05 0.05 0.05"/>
            </geometry>
        </collision>
    </link>
    <!-- Prismatic for rear left suspension -->
    <joint name="susp_rear_left_prismatic" type="prismatic">
        <origin xyz="-0.5 0.298 0.0" rpy="0.0 0.0 0.0"/>
        <parent link="chassis"/>
        <child link="suspension_rear_left"/>
        <axis xyz="0.0 0.0 -1.0"/>
        <limit lower="-0.0375" upper="0.0375" effort="10.0" velocity="-1.0"/>
        <dynamics damping="100"/>
    </joint>
    <!-- Wheel rear left -->
    <link name="wheel_rear_left">
        <inertial>
            <origin xyz="-0.5 0.298 0.15" rpy="-1.5707963267949 0.0 0.0"/>
            <mass value="0.5"/>
            <inertia ixx="0.0030791" ixy="0.0030791" ixz="0.005625" iyy="0.0" iyz="0.0" izz="0.0"/>
        </inertial>
        <visual name="wheel_rl_visual">
            <origin xyz="0.0 0.0 0.0" rpy="0.0 0.0 0.0"/>
            <geometry>
                <cylinder radius="0.15" length="0.08"/>
            </geometry>
            <material name="">
                <color rgba="1.0 0.0 0.0 1.0"/>
                <texture filename=""/>
            </material>
        </visual>
        <collision>
            <origin xyz="0.0 0.0 0.0" rpy="0.0 0.0 0.0"/>
            <geometry>
                <cylinder radius="0.15" length="0.08"/>
            </geometry>
        </collision>
    </link>
    <joint name="wheel_rl_joint" type="continuous">
        <origin xyz="0.0 0.0 0.0" rpy="-1.5707963267949 0.0 0.0"/>
        <parent link="suspension_rear_left"/>
        <child link="wheel_rear_left"/>
        <axis xyz="0.0 0.0 1.0"/>
        <dynamics damping="0.5"/>
    </joint>
</robot>